2021-10-27 16:17:28,317 Downloading artifact
wandb: ERROR Attempted to fetch artifact without alias (e.g. "<artifact_name>:v3" or "<artifact_name>:latest")
Traceback (most recent call last):
  File "/home/dora/miniconda3/envs/mlflow-484b576132a8d4f86bd93cd736b9c9cac218a14d/lib/python3.9/site-packages/wandb/apis/public.py", line 3077, in _load
    response = self.client.execute(
  File "/home/dora/miniconda3/envs/mlflow-484b576132a8d4f86bd93cd736b9c9cac218a14d/lib/python3.9/site-packages/wandb/old/retry.py", line 132, in wrapped_fn
    return retrier(*args, **kargs)
  File "/home/dora/miniconda3/envs/mlflow-484b576132a8d4f86bd93cd736b9c9cac218a14d/lib/python3.9/site-packages/wandb/old/retry.py", line 96, in __call__
    result = self._call_fn(*args, **kwargs)
  File "/home/dora/miniconda3/envs/mlflow-484b576132a8d4f86bd93cd736b9c9cac218a14d/lib/python3.9/site-packages/wandb/apis/public.py", line 181, in execute
    return self._client.execute(*args, **kwargs)
  File "/home/dora/miniconda3/envs/mlflow-484b576132a8d4f86bd93cd736b9c9cac218a14d/lib/python3.9/site-packages/wandb/vendor/gql-0.2.0/gql/client.py", line 52, in execute
    result = self._get_result(document, *args, **kwargs)
  File "/home/dora/miniconda3/envs/mlflow-484b576132a8d4f86bd93cd736b9c9cac218a14d/lib/python3.9/site-packages/wandb/vendor/gql-0.2.0/gql/client.py", line 60, in _get_result
    return self.transport.execute(document, *args, **kwargs)
  File "/home/dora/miniconda3/envs/mlflow-484b576132a8d4f86bd93cd736b9c9cac218a14d/lib/python3.9/site-packages/wandb/vendor/gql-0.2.0/gql/transport/requests.py", line 39, in execute
    request.raise_for_status()
  File "/home/dora/miniconda3/envs/mlflow-484b576132a8d4f86bd93cd736b9c9cac218a14d/lib/python3.9/site-packages/requests/models.py", line 953, in raise_for_status
    raise HTTPError(http_error_msg, response=self)
requests.exceptions.HTTPError: 400 Client Error: Bad Request for url: https://api.wandb.ai/graphql

During handling of the above exception, another exception occurred:

Traceback (most recent call last):
  File "/home/dora/miniconda3/envs/mlflow-484b576132a8d4f86bd93cd736b9c9cac218a14d/lib/python3.9/site-packages/wandb/apis/normalize.py", line 24, in wrapper
    return func(*args, **kwargs)
  File "/home/dora/miniconda3/envs/mlflow-484b576132a8d4f86bd93cd736b9c9cac218a14d/lib/python3.9/site-packages/wandb/apis/public.py", line 520, in artifact
    artifact = Artifact(self.client, entity, project, artifact_name)
  File "/home/dora/miniconda3/envs/mlflow-484b576132a8d4f86bd93cd736b9c9cac218a14d/lib/python3.9/site-packages/wandb/apis/public.py", line 2583, in __init__
    self._load()
  File "/home/dora/miniconda3/envs/mlflow-484b576132a8d4f86bd93cd736b9c9cac218a14d/lib/python3.9/site-packages/wandb/apis/public.py", line 3089, in _load
    raise ValueError(
ValueError: Attempted to fetch artifact without alias (e.g. "<artifact_name>:v3" or "<artifact_name>:latest")

During handling of the above exception, another exception occurred:

Traceback (most recent call last):
  File "/home/dora/github/nd0821-c2-build-model-workflow-exercises/lesson-5-final-pipeline-release-and-deploy/exercises/Udacity_genre_classification/preprocess/run.py", line 80, in <module>
    go(args)
  File "/home/dora/github/nd0821-c2-build-model-workflow-exercises/lesson-5-final-pipeline-release-and-deploy/exercises/Udacity_genre_classification/preprocess/run.py", line 19, in go
    artifact = run.use_artifact(args.input_artifact)
  File "/home/dora/miniconda3/envs/mlflow-484b576132a8d4f86bd93cd736b9c9cac218a14d/lib/python3.9/site-packages/wandb/sdk/wandb_run.py", line 1957, in use_artifact
    artifact = public_api.artifact(type=type, name=name)
  File "/home/dora/miniconda3/envs/mlflow-484b576132a8d4f86bd93cd736b9c9cac218a14d/lib/python3.9/site-packages/wandb/apis/normalize.py", line 62, in wrapper
    six.reraise(CommError, CommError(message, err), sys.exc_info()[2])
  File "/home/dora/miniconda3/envs/mlflow-484b576132a8d4f86bd93cd736b9c9cac218a14d/lib/python3.9/site-packages/six.py", line 718, in reraise
    raise value.with_traceback(tb)
  File "/home/dora/miniconda3/envs/mlflow-484b576132a8d4f86bd93cd736b9c9cac218a14d/lib/python3.9/site-packages/wandb/apis/normalize.py", line 24, in wrapper
    return func(*args, **kwargs)
  File "/home/dora/miniconda3/envs/mlflow-484b576132a8d4f86bd93cd736b9c9cac218a14d/lib/python3.9/site-packages/wandb/apis/public.py", line 520, in artifact
    artifact = Artifact(self.client, entity, project, artifact_name)
  File "/home/dora/miniconda3/envs/mlflow-484b576132a8d4f86bd93cd736b9c9cac218a14d/lib/python3.9/site-packages/wandb/apis/public.py", line 2583, in __init__
    self._load()
  File "/home/dora/miniconda3/envs/mlflow-484b576132a8d4f86bd93cd736b9c9cac218a14d/lib/python3.9/site-packages/wandb/apis/public.py", line 3089, in _load
    raise ValueError(
wandb.errors.error.CommError: Attempted to fetch artifact without alias (e.g. "<artifact_name>:v3" or "<artifact_name>:latest")
